Workbook

Sheet Setup
A1: TRANSFECTION OPTIMISATION CALCULATOR
B3: GENERAL PARAMETERS | E3: CELL PARAMETERS | H3: REAGENT PARAMETERS
B4: Total wells (per transf) | C4: 12 | E4: Cells/well (M) | F4: 0.03 | H4: PEI stock (µg/µl) | I4: 1
B5: DNA/well (ng) | C5: 100 | E5: DMEM/well (µl) | F5: 100 | H5: OptiMEM lot #
B6: OptiMEM (µl/well) | C6: 10 | E6: Plate format | F6: 96-well | H6: PEI lot #
B7: PEI:DNA ratio | C7: 3
B8: Margin factor (×) | C8: 1.2
B10: DNA STOCK INVENTORY
B11: DNA name | C11: Stock conc. (ng/µl) | E11: Notes
B12: HiBiT-AT1R | C12: 10 | E12: Receptor
B13: arr3 | C13: 79 | E13: LgBiT membrane anchor
E14: SmBiT sensor
B15: pcDNA | C15: 1000 | E15: Empty vector / filler
B20: Filler DNA row # | C20: 4 | E20: ← Which row above is the filler (1-8)
B22: CALCULATED SUMMARY (per condition)
B23: Total DNA / condition (ng) | C23: =C5*C4 -> 1200
B24: Total DNA × margin (ng) | C24: =C5*C4*C8 -> 1440
B25: PEI / condition (µl) | C25: =((C5*C4)*C7)/1000/I4 -> 3.6
B26: OptiMEM for DNA (µl) | C26: =(C6*C4)/2 -> 60
B27: OptiMEM for PEI (µl) | C27: =(C6*C4)/2 -> 60
B28: DMEM / condition (µl) | C28: =F5*C4 -> 1200
B29: Cells / condition (M) | C29: =F4*C4 -> 0.36
B31: Yellow cells = user inputs | Blue cells = auto-calculated

Sheet PEI Mix
A1: PEI MIX PREPARATION
B3: PEI MASTER MIX | E3: CELL SUSPENSION
B4: # conditions to prepare | C4: 8 | E4: DMEM total (µl) | F4: =Setup!F5*Setup!C4*Setup!C8*C4 -> 11520
B5: PEI per condition (µl) | C5: =((Setup!C5*Setup!C4)*Setup!C7)/1000/Setup!I4 -> 3.6 | E5: Total cells needed (M) | F5: =Setup!F4*Setup!C4*Setup!C8*C4 -> 3.456
B6: Total PEI needed (µl) | C6: =C5*C4*Setup!C8 -> 34.56 | E6: Cell suspension vol/well (µl) | F6: =Setup!F5*Setup!C4 -> 1200
B7: OptiMEM for PEI (µl/condition) | C7: =(Setup!C6*Setup!C4)/2 -> 60
B8: Total OptiMEM for PEI (µl) | C8: =C7*C4*Setup!C8 -> 576
B11: PROTOCOL REMINDER
B12: 1. Prepare DNA + OptiMEM mixes per condition (see DNA Mixes sheet)
B13: 2. Prepare PEI + OptiMEM master mix (values above)
B14: 3. Add equal volume of PEI/OptiMEM to each DNA/OptiMEM tube
B15: 4. Incubate 15-20 min at RT
B16: 5. Add transfection complex to wells
B17: 6. Add cell suspension to wells
B18: 7. Incubate at 37°C, 5% CO₂

Sheet DNA Mixes
A1: DNA MIX CONDITIONS
C3: EXPERIMENT GRID SETUP
C4: Columns across (Dim A): | F4: 4 | G4: ← e.g. 3 receptor concentrations
C5: Row groups down (Dim B): | F5: 2 | G5: ← e.g. 2 LgBiT concentrations
C6: Total conditions: | F6: 8 | G6: Unused blocks (greyed headers) are hidden when % cells are left empty
C8: no receptor | H8: low hibit | M8: med hibit | R8: high hibit | W8: Condition 5
A9: hibit | C9: ="A1: "&C8 -> A1: no receptor | H9: ="A2: "&H8 -> A2: low hibit | M9: ="A3: "&M8 -> A3: med hibit | R9: ="A4: "&R8 -> A4: high hibit | W9: ="A5: "&W8 -> A5: Condition 5
C10: DNA name | D10: % | E10: ng | F10: µl | H10: DNA name | I10: % | J10: ng | K10: µl | M10: DNA name | N10: % | O10: ng | P10: µl | R10: DNA name | S10: % | T10: ng | U10: µl | W10: DNA name | X10: % | Y10: ng | Z10: µl
C11: =Setup!B12 -> HiBiT-AT1R | D11: 0 | E11: =IF(D11="",0,(Setup!C5*Setup!C4)*D11/100) -> 0 | F11: =IF(OR(Setup!C12="",Setup!C12=0,E11=0),"—",E11/Setup!C12) -> — | H11: =Setup!B12 -> HiBiT-AT1R | I11: 0.5 | J11: =IF(I11="",0,(Setup!C5*Setup!C4)*I11/100) -> 6 | K11: =IF(OR(Setup!C12="",Setup!C12=0,J11=0),"—",J11/Setup!C12) -> 0.6 | M11: =Setup!B12 -> HiBiT-AT1R | N11: 1 | O11: =IF(N11="",0,(Setup!C5*Setup!C4)*N11/100) -> 12 | P11: =IF(OR(Setup!C12="",Setup!C12=0,O11=0),"—",O11/Setup!C12) -> 1.2 | R11: =Setup!B12 -> HiBiT-AT1R | S11: 5 | T11: =IF(S11="",0,(Setup!C5*Setup!C4)*S11/100) -> 60 | U11: =IF(OR(Setup!C12="",Setup!C12=0,T11=0),"—",T11/Setup!C12) -> 6 | W11: =Setup!B12 -> HiBiT-AT1R | Y11: =IF(X11="",0,(Setup!C5*Setup!C4)*X11/100) -> 0 | Z11: =IF(OR(Setup!C12="",Setup!C12=0,Y11=0),"—",Y11/Setup!C12) -> —
C12: =Setup!B13 -> arr3 | D12: 0 | E12: =IF(D12="",0,(Setup!C5*Setup!C4)*D12/100) -> 0 | F12: =IF(OR(Setup!C13="",Setup!C13=0,E12=0),"—",E12/Setup!C13) -> — | H12: =Setup!B13 -> arr3 | I12: 0 | J12: =IF(I12="",0,(Setup!C5*Setup!C4)*I12/100) -> 0 | K12: =IF(OR(Setup!C13="",Setup!C13=0,J12=0),"—",J12/Setup!C13) -> — | M12: =Setup!B13 -> arr3 | N12: 0 | O12: =IF(N12="",0,(Setup!C5*Setup!C4)*N12/100) -> 0 | P12: =IF(OR(Setup!C13="",Setup!C13=0,O12=0),"—",O12/Setup!C13) -> — | R12: =Setup!B13 -> arr3 | S12: 0 | T12: =IF(S12="",0,(Setup!C5*Setup!C4)*S12/100) -> 0 | U12: =IF(OR(Setup!C13="",Setup!C13=0,T12=0),"—",T12/Setup!C13) -> — | W12: =Setup!B13 -> arr3 | Y12: =IF(X12="",0,(Setup!C5*Setup!C4)*X12/100) -> 0 | Z12: =IF(OR(Setup!C13="",Setup!C13=0,Y12=0),"—",Y12/Setup!C13) -> —
C13: =Setup!B14 -> 0 | D13: 0 | E13: =IF(D13="",0,(Setup!C5*Setup!C4)*D13/100) -> 0 | F13: =IF(OR(Setup!C14="",Setup!C14=0,E13=0),"—",E13/Setup!C14) -> — | H13: =Setup!B14 -> 0 | I13: 0 | J13: =IF(I13="",0,(Setup!C5*Setup!C4)*I13/100) -> 0 | K13: =IF(OR(Setup!C14="",Setup!C14=0,J13=0),"—",J13/Setup!C14) -> — | M13: =Setup!B14 -> 0 | O13: =IF(N13="",0,(Setup!C5*Setup!C4)*N13/100) -> 0 | P13: =IF(OR(Setup!C14="",Setup!C14=0,O13=0),"—",O13/Setup!C14) -> — | R13: =Setup!B14 -> 0 | T13: =IF(S13="",0,(Setup!C5*Setup!C4)*S13/100) -> 0 | U13: =IF(OR(Setup!C14="",Setup!C14=0,T13=0),"—",T13/Setup!C14) -> — | W13: =Setup!B14 -> 0 | Y13: =IF(X13="",0,(Setup!C5*Setup!C4)*X13/100) -> 0 | Z13: =IF(OR(Setup!C14="",Setup!C14=0,Y13=0),"—",Y13/Setup!C14) -> —
C14: =Setup!B15 -> pcDNA | D14: =MAX(0,100-(IF(D11="",0,D11)+IF(D12="",0,D12)+IF(D13="",0,D13)+IF(D15="",0,D15)+IF(D16="",0,D16)+IF(D17="",0,D17)+IF(D18="",0,D18))) -> 100 | E14: =IF(D14="",0,(Setup!C5*Setup!C4)*D14/100) -> 1200 | F14: =IF(OR(Setup!C15="",Setup!C15=0,E14=0),"—",E14/Setup!C15) -> 1.2 | H14: =Setup!B15 -> pcDNA | I14: =MAX(0,100-(IF(I11="",0,I11)+IF(I12="",0,I12)+IF(I13="",0,I13)+IF(I15="",0,I15)+IF(I16="",0,I16)+IF(I17="",0,I17)+IF(I18="",0,I18))) -> 99.5 | J14: =IF(I14="",0,(Setup!C5*Setup!C4)*I14/100) -> 1194 | K14: =IF(OR(Setup!C15="",Setup!C15=0,J14=0),"—",J14/Setup!C15) -> 1.194 | M14: =Setup!B15 -> pcDNA | N14: =MAX(0,100-(IF(N11="",0,N11)+IF(N12="",0,N12)+IF(N13="",0,N13)+IF(N15="",0,N15)+IF(N16="",0,N16)+IF(N17="",0,N17)+IF(N18="",0,N18))) -> 99 | O14: =IF(N14="",0,(Setup!C5*Setup!C4)*N14/100) -> 1188 | P14: =IF(OR(Setup!C15="",Setup!C15=0,O14=0),"—",O14/Setup!C15) -> 1.188 | R14: =Setup!B15 -> pcDNA | S14: =MAX(0,100-(IF(S11="",0,S11)+IF(S12="",0,S12)+IF(S13="",0,S13)+IF(S15="",0,S15)+IF(S16="",0,S16)+IF(S17="",0,S17)+IF(S18="",0,S18))) -> 95 | T14: =IF(S14="",0,(Setup!C5*Setup!C4)*S14/100) -> 1140 | U14: =IF(OR(Setup!C15="",Setup!C15=0,T14=0),"—",T14/Setup!C15) -> 1.14 | W14: =Setup!B15 -> pcDNA | X14: =MAX(0,100-(IF(X11="",0,X11)+IF(X12="",0,X12)+IF(X13="",0,X13)+IF(X15="",0,X15)+IF(X16="",0,X16)+IF(X17="",0,X17)+IF(X18="",0,X18))) -> 100 | Y14: =IF(X14="",0,(Setup!C5*Setup!C4)*X14/100) -> 1200 | Z14: =IF(OR(Setup!C15="",Setup!C15=0,Y14=0),"—",Y14/Setup!C15) -> 1.2
C15: =Setup!B16 -> 0 | E15: =IF(D15="",0,(Setup!C5*Setup!C4)*D15/100) -> 0 | F15: =IF(OR(Setup!C16="",Setup!C16=0,E15=0),"—",E15/Setup!C16) -> — | H15: =Setup!B16 -> 0 | J15: =IF(I15="",0,(Setup!C5*Setup!C4)*I15/100) -> 0 | K15: =IF(OR(Setup!C16="",Setup!C16=0,J15=0),"—",J15/Setup!C16) -> — | M15: =Setup!B16 -> 0 | O15: =IF(N15="",0,(Setup!C5*Setup!C4)*N15/100) -> 0 | P15: =IF(OR(Setup!C16="",Setup!C16=0,O15=0),"—",O15/Setup!C16) -> — | R15: =Setup!B16 -> 0 | T15: =IF(S15="",0,(Setup!C5*Setup!C4)*S15/100) -> 0 | U15: =IF(OR(Setup!C16="",Setup!C16=0,T15=0),"—",T15/Setup!C16) -> — | W15: =Setup!B16 -> 0 | Y15: =IF(X15="",0,(Setup!C5*Setup!C4)*X15/100) -> 0 | Z15: =IF(OR(Setup!C16="",Setup!C16=0,Y15=0),"—",Y15/Setup!C16) -> —
C16: =Setup!B17 -> 0 | E16: =IF(D16="",0,(Setup!C5*Setup!C4)*D16/100) -> 0 | F16: =IF(OR(Setup!C17="",Setup!C17=0,E16=0),"—",E16/Setup!C17) -> — | H16: =Setup!B17 -> 0 | J16: =IF(I16="",0,(Setup!C5*Setup!C4)*I16/100) -> 0 | K16: =IF(OR(Setup!C17="",Setup!C17=0,J16=0),"—",J16/Setup!C17) -> — | M16: =Setup!B17 -> 0 | O16: =IF(N16="",0,(Setup!C5*Setup!C4)*N16/100) -> 0 | P16: =IF(OR(Setup!C17="",Setup!C17=0,O16=0),"—",O16/Setup!C17) -> — | R16: =Setup!B17 -> 0 | T16: =IF(S16="",0,(Setup!C5*Setup!C4)*S16/100) -> 0 | U16: =IF(OR(Setup!C17="",Setup!C17=0,T16=0),"—",T16/Setup!C17) -> — | W16: =Setup!B17 -> 0 | Y16: =IF(X16="",0,(Setup!C5*Setup!C4)*X16/100) -> 0 | Z16: =IF(OR(Setup!C17="",Setup!C17=0,Y16=0),"—",Y16/Setup!C17) -> —
C17: =Setup!B18 -> 0 | E17: =IF(D17="",0,(Setup!C5*Setup!C4)*D17/100) -> 0 | F17: =IF(OR(Setup!C18="",Setup!C18=0,E17=0),"—",E17/Setup!C18) -> — | H17: =Setup!B18 -> 0 | J17: =IF(I17="",0,(Setup!C5*Setup!C4)*I17/100) -> 0 | K17: =IF(OR(Setup!C18="",Setup!C18=0,J17=0),"—",J17/Setup!C18) -> — | M17: =Setup!B18 -> 0 | O17: =IF(N17="",0,(Setup!C5*Setup!C4)*N17/100) -> 0 | P17: =IF(OR(Setup!C18="",Setup!C18=0,O17=0),"—",O17/Setup!C18) -> — | R17: =Setup!B18 -> 0 | T17: =IF(S17="",0,(Setup!C5*Setup!C4)*S17/100) -> 0 | U17: =IF(OR(Setup!C18="",Setup!C18=0,T17=0),"—",T17/Setup!C18) -> — | W17: =Setup!B18 -> 0 | Y17: =IF(X17="",0,(Setup!C5*Setup!C4)*X17/100) -> 0 | Z17: =IF(OR(Setup!C18="",Setup!C18=0,Y17=0),"—",Y17/Setup!C18) -> —
C18: =Setup!B19 -> 0 | E18: =IF(D18="",0,(Setup!C5*Setup!C4)*D18/100) -> 0 | F18: =IF(OR(Setup!C19="",Setup!C19=0,E18=0),"—",E18/Setup!C19) -> — | H18: =Setup!B19 -> 0 | J18: =IF(I18="",0,(Setup!C5*Setup!C4)*I18/100) -> 0 | K18: =IF(OR(Setup!C19="",Setup!C19=0,J18=0),"—",J18/Setup!C19) -> — | M18: =Setup!B19 -> 0 | O18: =IF(N18="",0,(Setup!C5*Setup!C4)*N18/100) -> 0 | P18: =IF(OR(Setup!C19="",Setup!C19=0,O18=0),"—",O18/Setup!C19) -> — | R18: =Setup!B19 -> 0 | T18: =IF(S18="",0,(Setup!C5*Setup!C4)*S18/100) -> 0 | U18: =IF(OR(Setup!C19="",Setup!C19=0,T18=0),"—",T18/Setup!C19) -> — | W18: =Setup!B19 -> 0 | Y18: =IF(X18="",0,(Setup!C5*Setup!C4)*X18/100) -> 0 | Z18: =IF(OR(Setup!C19="",Setup!C19=0,Y18=0),"—",Y18/Setup!C19) -> —
C19: TOTAL | D19: =SUMPRODUCT((D11:D18<>"")*(D11:D18)) -> 100 | E19: =SUM(E11:E18) -> 1200 | F19: =SUM(F11:F18) -> 1.2 | H19: TOTAL | I19: =SUMPRODUCT((I11:I18<>"")*(I11:I18)) -> 100 | J19: =SUM(J11:J18) -> 1200 | K19: =SUM(K11:K18) -> 1.794 | M19: TOTAL | N19: =SUMPRODUCT((N11:N18<>"")*(N11:N18)) -> 100 | O19: =SUM(O11:O18) -> 1200 | P19: =SUM(P11:P18) -> 2.388 | R19: TOTAL | S19: =SUMPRODUCT((S11:S18<>"")*(S11:S18)) -> 100 | T19: =SUM(T11:T18) -> 1200 | U19: =SUM(U11:U18) -> 7.14 | W19: TOTAL | X19: =SUMPRODUCT((X11:X18<>"")*(X11:X18)) -> 100 | Y19: =SUM(Y11:Y18) -> 1200 | Z19: =SUM(Z11:Z18) -> 1.2
C20: =IF(D19=100,"✓ OK","⚠ ≠ 100%") -> ✓ OK | E20: =Setup!C26 -> 60 | H20: =IF(I19=100,"✓ OK","⚠ ≠ 100%") -> ✓ OK | J20: =Setup!C26 -> 60 | M20: =IF(N19=100,"✓ OK","⚠ ≠ 100%") -> ✓ OK | O20: =Setup!C26 -> 60 | R20: =IF(S19=100,"✓ OK","⚠ ≠ 100%") -> ✓ OK | T20: =Setup!C26 -> 60 | W20: =IF(X19=100,"✓ OK","⚠ ≠ 100%") -> ✓ OK | Y20: =Setup!C26 -> 60
A22: hibit+arr | C22: ="C1: "&C8 -> C1: no receptor | H22: ="C2: "&H8 -> C2: low hibit | M22: ="C3: "&M8 -> C3: med hibit | R22: ="C4: "&R8 -> C4: high hibit | W22: ="C5: "&W8 -> C5: Condition 5
C23: DNA name | D23: % | E23: ng | F23: µl | H23: DNA name | I23: % | J23: ng | K23: µl | M23: DNA name | N23: % | O23: ng | P23: µl | R23: DNA name | S23: % | T23: ng | U23: µl | W23: DNA name | X23: % | Y23: ng | Z23: µl
C24: =Setup!B12 -> HiBiT-AT1R | E24: =IF(D24="",0,(Setup!C5*Setup!C4)*D24/100) -> 0 | F24: =IF(OR(Setup!C12="",Setup!C12=0,E24=0),"—",E24/Setup!C12) -> — | H24: =Setup!B12 -> HiBiT-AT1R | I24: 0.5 | J24: =IF(I24="",0,(Setup!C5*Setup!C4)*I24/100) -> 6 | K24: =IF(OR(Setup!C12="",Setup!C12=0,J24=0),"—",J24/Setup!C12) -> 0.6 | M24: =Setup!B12 -> HiBiT-AT1R | N24: 1 | O24: =IF(N24="",0,(Setup!C5*Setup!C4)*N24/100) -> 12 | P24: =IF(OR(Setup!C12="",Setup!C12=0,O24=0),"—",O24/Setup!C12) -> 1.2 | R24: =Setup!B12 -> HiBiT-AT1R | S24: 5 | T24: =IF(S24="",0,(Setup!C5*Setup!C4)*S24/100) -> 60 | U24: =IF(OR(Setup!C12="",Setup!C12=0,T24=0),"—",T24/Setup!C12) -> 6 | W24: =Setup!B12 -> HiBiT-AT1R | Y24: =IF(X24="",0,(Setup!C5*Setup!C4)*X24/100) -> 0 | Z24: =IF(OR(Setup!C12="",Setup!C12=0,Y24=0),"—",Y24/Setup!C12) -> —
C25: =Setup!B13 -> arr3 | E25: =IF(D25="",0,(Setup!C5*Setup!C4)*D25/100) -> 0 | F25: =IF(OR(Setup!C13="",Setup!C13=0,E25=0),"—",E25/Setup!C13) -> — | H25: =Setup!B13 -> arr3 | I25: 5 | J25: =IF(I25="",0,(Setup!C5*Setup!C4)*I25/100) -> 60 | K25: =IF(OR(Setup!C13="",Setup!C13=0,J25=0),"—",J25/Setup!C13) -> 0.75949367 | M25: =Setup!B13 -> arr3 | N25: 10 | O25: =IF(N25="",0,(Setup!C5*Setup!C4)*N25/100) -> 120 | P25: =IF(OR(Setup!C13="",Setup!C13=0,O25=0),"—",O25/Setup!C13) -> 1.5189873 | R25: =Setup!B13 -> arr3 | S25: 50 | T25: =IF(S25="",0,(Setup!C5*Setup!C4)*S25/100) -> 600 | U25: =IF(OR(Setup!C13="",Setup!C13=0,T25=0),"—",T25/Setup!C13) -> 7.5949367 | W25: =Setup!B13 -> arr3 | Y25: =IF(X25="",0,(Setup!C5*Setup!C4)*X25/100) -> 0 | Z25: =IF(OR(Setup!C13="",Setup!C13=0,Y25=0),"—",Y25/Setup!C13) -> —
C26: =Setup!B14 -> 0 | E26: =IF(D26="",0,(Setup!C5*Setup!C4)*D26/100) -> 0 | F26: =IF(OR(Setup!C14="",Setup!C14=0,E26=0),"—",E26/Setup!C14) -> — | H26: =Setup!B14 -> 0 | J26: =IF(I26="",0,(Setup!C5*Setup!C4)*I26/100) -> 0 | K26: =IF(OR(Setup!C14="",Setup!C14=0,J26=0),"—",J26/Setup!C14) -> — | M26: =Setup!B14 -> 0 | O26: =IF(N26="",0,(Setup!C5*Setup!C4)*N26/100) -> 0 | P26: =IF(OR(Setup!C14="",Setup!C14=0,O26=0),"—",O26/Setup!C14) -> — | R26: =Setup!B14 -> 0 | T26: =IF(S26="",0,(Setup!C5*Setup!C4)*S26/100) -> 0 | U26: =IF(OR(Setup!C14="",Setup!C14=0,T26=0),"—",T26/Setup!C14) -> — | W26: =Setup!B14 -> 0 | Y26: =IF(X26="",0,(Setup!C5*Setup!C4)*X26/100) -> 0 | Z26: =IF(OR(Setup!C14="",Setup!C14=0,Y26=0),"—",Y26/Setup!C14) -> —
C27: =Setup!B15 -> pcDNA | D27: =MAX(0,100-(IF(D24="",0,D24)+IF(D25="",0,D25)+IF(D26="",0,D26)+IF(D28="",0,D28)+IF(D29="",0,D29)+IF(D30="",0,D30)+IF(D31="",0,D31))) -> 100 | E27: =IF(D27="",0,(Setup!C5*Setup!C4)*D27/100) -> 1200 | F27: =IF(OR(Setup!C15="",Setup!C15=0,E27=0),"—",E27/Setup!C15) -> 1.2 | H27: =Setup!B15 -> pcDNA | I27: =MAX(0,100-(IF(I24="",0,I24)+IF(I25="",0,I25)+IF(I26="",0,I26)+IF(I28="",0,I28)+IF(I29="",0,I29)+IF(I30="",0,I30)+IF(I31="",0,I31))) -> 94.5 | J27: =IF(I27="",0,(Setup!C5*Setup!C4)*I27/100) -> 1134 | K27: =IF(OR(Setup!C15="",Setup!C15=0,J27=0),"—",J27/Setup!C15) -> 1.134 | M27: =Setup!B15 -> pcDNA | N27: =MAX(0,100-(IF(N24="",0,N24)+IF(N25="",0,N25)+IF(N26="",0,N26)+IF(N28="",0,N28)+IF(N29="",0,N29)+IF(N30="",0,N30)+IF(N31="",0,N31))) -> 89 | O27: =IF(N27="",0,(Setup!C5*Setup!C4)*N27/100) -> 1068 | P27: =IF(OR(Setup!C15="",Setup!C15=0,O27=0),"—",O27/Setup!C15) -> 1.068 | R27: =Setup!B15 -> pcDNA | S27: =MAX(0,100-(IF(S24="",0,S24)+IF(S25="",0,S25)+IF(S26="",0,S26)+IF(S28="",0,S28)+IF(S29="",0,S29)+IF(S30="",0,S30)+IF(S31="",0,S31))) -> 45 | T27: =IF(S27="",0,(Setup!C5*Setup!C4)*S27/100) -> 540 | U27: =IF(OR(Setup!C15="",Setup!C15=0,T27=0),"—",T27/Setup!C15) -> 0.54 | W27: =Setup!B15 -> pcDNA | X27: =MAX(0,100-(IF(X24="",0,X24)+IF(X25="",0,X25)+IF(X26="",0,X26)+IF(X28="",0,X28)+IF(X29="",0,X29)+IF(X30="",0,X30)+IF(X31="",0,X31))) -> 100 | Y27: =IF(X27="",0,(Setup!C5*Setup!C4)*X27/100) -> 1200 | Z27: =IF(OR(Setup!C15="",Setup!C15=0,Y27=0),"—",Y27/Setup!C15) -> 1.2
C28: =Setup!B16 -> 0 | E28: =IF(D28="",0,(Setup!C5*Setup!C4)*D28/100) -> 0 | F28: =IF(OR(Setup!C16="",Setup!C16=0,E28=0),"—",E28/Setup!C16) -> — | H28: =Setup!B16 -> 0 | J28: =IF(I28="",0,(Setup!C5*Setup!C4)*I28/100) -> 0 | K28: =IF(OR(Setup!C16="",Setup!C16=0,J28=0),"—",J28/Setup!C16) -> — | M28: =Setup!B16 -> 0 | O28: =IF(N28="",0,(Setup!C5*Setup!C4)*N28/100) -> 0 | P28: =IF(OR(Setup!C16="",Setup!C16=0,O28=0),"—",O28/Setup!C16) -> — | R28: =Setup!B16 -> 0 | T28: =IF(S28="",0,(Setup!C5*Setup!C4)*S28/100) -> 0 | U28: =IF(OR(Setup!C16="",Setup!C16=0,T28=0),"—",T28/Setup!C16) -> — | W28: =Setup!B16 -> 0 | Y28: =IF(X28="",0,(Setup!C5*Setup!C4)*X28/100) -> 0 | Z28: =IF(OR(Setup!C16="",Setup!C16=0,Y28=0),"—",Y28/Setup!C16) -> —
C29: =Setup!B17 -> 0 | E29: =IF(D29="",0,(Setup!C5*Setup!C4)*D29/100) -> 0 | F29: =IF(OR(Setup!C17="",Setup!C17=0,E29=0),"—",E29/Setup!C17) -> — | H29: =Setup!B17 -> 0 | J29: =IF(I29="",0,(Setup!C5*Setup!C4)*I29/100) -> 0 | K29: =IF(OR(Setup!C17="",Setup!C17=0,J29=0),"—",J29/Setup!C17) -> — | M29: =Setup!B17 -> 0 | O29: =IF(N29="",0,(Setup!C5*Setup!C4)*N29/100) -> 0 | P29: =IF(OR(Setup!C17="",Setup!C17=0,O29=0),"—",O29/Setup!C17) -> — | R29: =Setup!B17 -> 0 | T29: =IF(S29="",0,(Setup!C5*Setup!C4)*S29/100) -> 0 | U29: =IF(OR(Setup!C17="",Setup!C17=0,T29=0),"—",T29/Setup!C17) -> — | W29: =Setup!B17 -> 0 | Y29: =IF(X29="",0,(Setup!C5*Setup!C4)*X29/100) -> 0 | Z29: =IF(OR(Setup!C17="",Setup!C17=0,Y29=0),"—",Y29/Setup!C17) -> —
C30: =Setup!B18 -> 0 | E30: =IF(D30="",0,(Setup!C5*Setup!C4)*D30/100) -> 0 | F30: =IF(OR(Setup!C18="",Setup!C18=0,E30=0),"—",E30/Setup!C18) -> — | H30: =Setup!B18 -> 0 | J30: =IF(I30="",0,(Setup!C5*Setup!C4)*I30/100) -> 0 | K30: =IF(OR(Setup!C18="",Setup!C18=0,J30=0),"—",J30/Setup!C18) -> — | M30: =Setup!B18 -> 0 | O30: =IF(N30="",0,(Setup!C5*Setup!C4)*N30/100) -> 0 | P30: =IF(OR(Setup!C18="",Setup!C18=0,O30=0),"—",O30/Setup!C18) -> — | R30: =Setup!B18 -> 0 | T30: =IF(S30="",0,(Setup!C5*Setup!C4)*S30/100) -> 0 | U30: =IF(OR(Setup!C18="",Setup!C18=0,T30=0),"—",T30/Setup!C18) -> — | W30: =Setup!B18 -> 0 | Y30: =IF(X30="",0,(Setup!C5*Setup!C4)*X30/100) -> 0 | Z30: =IF(OR(Setup!C18="",Setup!C18=0,Y30=0),"—",Y30/Setup!C18) -> —
C31: =Setup!B19 -> 0 | E31: =IF(D31="",0,(Setup!C5*Setup!C4)*D31/100) -> 0 | F31: =IF(OR(Setup!C19="",Setup!C19=0,E31=0),"—",E31/Setup!C19) -> — | H31: =Setup!B19 -> 0 | J31: =IF(I31="",0,(Setup!C5*Setup!C4)*I31/100) -> 0 | K31: =IF(OR(Setup!C19="",Setup!C19=0,J31=0),"—",J31/Setup!C19) -> — | M31: =Setup!B19 -> 0 | O31: =IF(N31="",0,(Setup!C5*Setup!C4)*N31/100) -> 0 | P31: =IF(OR(Setup!C19="",Setup!C19=0,O31=0),"—",O31/Setup!C19) -> — | R31: =Setup!B19 -> 0 | T31: =IF(S31="",0,(Setup!C5*Setup!C4)*S31/100) -> 0 | U31: =IF(OR(Setup!C19="",Setup!C19=0,T31=0),"—",T31/Setup!C19) -> — | W31: =Setup!B19 -> 0 | Y31: =IF(X31="",0,(Setup!C5*Setup!C4)*X31/100) -> 0 | Z31: =IF(OR(Setup!C19="",Setup!C19=0,Y31=0),"—",Y31/Setup!C19) -> —
C32: TOTAL | D32: =SUMPRODUCT((D24:D31<>"")*(D24:D31)) -> 100 | E32: =SUM(E24:E31) -> 1200 | F32: =SUM(F24:F31) -> 1.2 | H32: TOTAL | I32: =SUMPRODUCT((I24:I31<>"")*(I24:I31)) -> 100 | J32: =SUM(J24:J31) -> 1200 | K32: =SUM(K24:K31) -> 2.4934937 | M32: TOTAL | N32: =SUMPRODUCT((N24:N31<>"")*(N24:N31)) -> 100 | O32: =SUM(O24:O31) -> 1200 | P32: =SUM(P24:P31) -> 3.7869873 | R32: TOTAL | S32: =SUMPRODUCT((S24:S31<>"")*(S24:S31)) -> 100 | T32: =SUM(T24:T31) -> 1200 | U32: =SUM(U24:U31) -> 14.134937 | W32: TOTAL | X32: =SUMPRODUCT((X24:X31<>"")*(X24:X31)) -> 100 | Y32: =SUM(Y24:Y31) -> 1200 | Z32: =SUM(Z24:Z31) -> 1.2
C33: =IF(D32=100,"✓ OK","⚠ ≠ 100%") -> ✓ OK | E33: =Setup!C26 -> 60 | H33: =IF(I32=100,"✓ OK","⚠ ≠ 100%") -> ✓ OK | J33: =Setup!C26 -> 60 | M33: =IF(N32=100,"✓ OK","⚠ ≠ 100%") -> ✓ OK | O33: =Setup!C26 -> 60 | R33: =IF(S32=100,"✓ OK","⚠ ≠ 100%") -> ✓ OK | T33: =Setup!C26 -> 60 | W33: =IF(X32=100,"✓ OK","⚠ ≠ 100%") -> ✓ OK | Y33: =Setup!C26 -> 60
A35: stable and arr (ignore title) | C35: ="E1: "&C8 -> E1: no receptor | H35: ="E2: "&H8 -> E2: low hibit | M35: ="E3: "&M8 -> E3: med hibit | R35: ="E4: "&R8 -> E4: high hibit | W35: ="E5: "&W8 -> E5: Condition 5
C36: DNA name | D36: % | E36: ng | F36: µl | H36: DNA name | I36: % | J36: ng | K36: µl | M36: DNA name | N36: % | O36: ng | P36: µl | R36: DNA name | S36: % | T36: ng | U36: µl | W36: DNA name | X36: % | Y36: ng | Z36: µl
C37: =Setup!B12 -> HiBiT-AT1R | E37: =IF(D37="",0,(Setup!C5*Setup!C4)*D37/100) -> 0 | F37: =IF(OR(Setup!C12="",Setup!C12=0,E37=0),"—",E37/Setup!C12) -> — | H37: =Setup!B12 -> HiBiT-AT1R | J37: =IF(I37="",0,(Setup!C5*Setup!C4)*I37/100) -> 0 | K37: =IF(OR(Setup!C12="",Setup!C12=0,J37=0),"—",J37/Setup!C12) -> — | M37: =Setup!B12 -> HiBiT-AT1R | O37: =IF(N37="",0,(Setup!C5*Setup!C4)*N37/100) -> 0 | P37: =IF(OR(Setup!C12="",Setup!C12=0,O37=0),"—",O37/Setup!C12) -> — | R37: =Setup!B12 -> HiBiT-AT1R | T37: =IF(S37="",0,(Setup!C5*Setup!C4)*S37/100) -> 0 | U37: =IF(OR(Setup!C12="",Setup!C12=0,T37=0),"—",T37/Setup!C12) -> — | W37: =Setup!B12 -> HiBiT-AT1R | Y37: =IF(X37="",0,(Setup!C5*Setup!C4)*X37/100) -> 0 | Z37: =IF(OR(Setup!C12="",Setup!C12=0,Y37=0),"—",Y37/Setup!C12) -> —
C38: =Setup!B13 -> arr3 | E38: =IF(D38="",0,(Setup!C5*Setup!C4)*D38/100) -> 0 | F38: =IF(OR(Setup!C13="",Setup!C13=0,E38=0),"—",E38/Setup!C13) -> — | H38: =Setup!B13 -> arr3 | J38: =IF(I38="",0,(Setup!C5*Setup!C4)*I38/100) -> 0 | K38: =IF(OR(Setup!C13="",Setup!C13=0,J38=0),"—",J38/Setup!C13) -> — | M38: =Setup!B13 -> arr3 | O38: =IF(N38="",0,(Setup!C5*Setup!C4)*N38/100) -> 0 | P38: =IF(OR(Setup!C13="",Setup!C13=0,O38=0),"—",O38/Setup!C13) -> — | R38: =Setup!B13 -> arr3 | T38: =IF(S38="",0,(Setup!C5*Setup!C4)*S38/100) -> 0 | U38: =IF(OR(Setup!C13="",Setup!C13=0,T38=0),"—",T38/Setup!C13) -> — | W38: =Setup!B13 -> arr3 | Y38: =IF(X38="",0,(Setup!C5*Setup!C4)*X38/100) -> 0 | Z38: =IF(OR(Setup!C13="",Setup!C13=0,Y38=0),"—",Y38/Setup!C13) -> —
C39: =Setup!B14 -> 0 | E39: =IF(D39="",0,(Setup!C5*Setup!C4)*D39/100) -> 0 | F39: =IF(OR(Setup!C14="",Setup!C14=0,E39=0),"—",E39/Setup!C14) -> — | H39: =Setup!B14 -> 0 | J39: =IF(I39="",0,(Setup!C5*Setup!C4)*I39/100) -> 0 | K39: =IF(OR(Setup!C14="",Setup!C14=0,J39=0),"—",J39/Setup!C14) -> — | M39: =Setup!B14 -> 0 | O39: =IF(N39="",0,(Setup!C5*Setup!C4)*N39/100) -> 0 | P39: =IF(OR(Setup!C14="",Setup!C14=0,O39=0),"—",O39/Setup!C14) -> — | R39: =Setup!B14 -> 0 | T39: =IF(S39="",0,(Setup!C5*Setup!C4)*S39/100) -> 0 | U39: =IF(OR(Setup!C14="",Setup!C14=0,T39=0),"—",T39/Setup!C14) -> — | W39: =Setup!B14 -> 0 | Y39: =IF(X39="",0,(Setup!C5*Setup!C4)*X39/100) -> 0 | Z39: =IF(OR(Setup!C14="",Setup!C14=0,Y39=0),"—",Y39/Setup!C14) -> —
C40: =Setup!B15 -> pcDNA | D40: =MAX(0,100-(IF(D37="",0,D37)+IF(D38="",0,D38)+IF(D39="",0,D39)+IF(D41="",0,D41)+IF(D42="",0,D42)+IF(D43="",0,D43)+IF(D44="",0,D44))) -> 100 | E40: =IF(D40="",0,(Setup!C5*Setup!C4)*D40/100) -> 1200 | F40: =IF(OR(Setup!C15="",Setup!C15=0,E40=0),"—",E40/Setup!C15) -> 1.2 | H40: =Setup!B15 -> pcDNA | I40: =MAX(0,100-(IF(I37="",0,I37)+IF(I38="",0,I38)+IF(I39="",0,I39)+IF(I41="",0,I41)+IF(I42="",0,I42)+IF(I43="",0,I43)+IF(I44="",0,I44))) -> 100 | J40: =IF(I40="",0,(Setup!C5*Setup!C4)*I40/100) -> 1200 | K40: =IF(OR(Setup!C15="",Setup!C15=0,J40=0),"—",J40/Setup!C15) -> 1.2 | M40: =Setup!B15 -> pcDNA | N40: =MAX(0,100-(IF(N37="",0,N37)+IF(N38="",0,N38)+IF(N39="",0,N39)+IF(N41="",0,N41)+IF(N42="",0,N42)+IF(N43="",0,N43)+IF(N44="",0,N44))) -> 100 | O40: =IF(N40="",0,(Setup!C5*Setup!C4)*N40/100) -> 1200 | P40: =IF(OR(Setup!C15="",Setup!C15=0,O40=0),"—",O40/Setup!C15) -> 1.2 | R40: =Setup!B15 -> pcDNA | S40: =MAX(0,100-(IF(S37="",0,S37)+IF(S38="",0,S38)+IF(S39="",0,S39)+IF(S41="",0,S41)+IF(S42="",0,S42)+IF(S43="",0,S43)+IF(S44="",0,S44))) -> 100 | T40: =IF(S40="",0,(Setup!C5*Setup!C4)*S40/100) -> 1200 | U40: =IF(OR(Setup!C15="",Setup!C15=0,T40=0),"—",T40/Setup!C15) -> 1.2 | W40: =Setup!B15 -> pcDNA | X40: =MAX(0,100-(IF(X37="",0,X37)+IF(X38="",0,X38)+IF(X39="",0,X39)+IF(X41="",0,X41)+IF(X42="",0,X42)+IF(X43="",0,X43)+IF(X44="",0,X44))) -> 100 | Y40: =IF(X40="",0,(Setup!C5*Setup!C4)*X40/100) -> 1200 | Z40: =IF(OR(Setup!C15="",Setup!C15=0,Y40=0),"—",Y40/Setup!C15) -> 1.2
C41: =Setup!B16 -> 0 | E41: =IF(D41="",0,(Setup!C5*Setup!C4)*D41/100) -> 0 | F41: =IF(OR(Setup!C16="",Setup!C16=0,E41=0),"—",E41/Setup!C16) -> — | H41: =Setup!B16 -> 0 | J41: =IF(I41="",0,(Setup!C5*Setup!C4)*I41/100) -> 0 | K41: =IF(OR(Setup!C16="",Setup!C16=0,J41=0),"—",J41/Setup!C16) -> — | M41: =Setup!B16 -> 0 | O41: =IF(N41="",0,(Setup!C5*Setup!C4)*N41/100) -> 0 | P41: =IF(OR(Setup!C16="",Setup!C16=0,O41=0),"—",O41/Setup!C16) -> — | R41: =Setup!B16 -> 0 | T41: =IF(S41="",0,(Setup!C5*Setup!C4)*S41/100) -> 0 | U41: =IF(OR(Setup!C16="",Setup!C16=0,T41=0),"—",T41/Setup!C16) -> — | W41: =Setup!B16 -> 0 | Y41: =IF(X41="",0,(Setup!C5*Setup!C4)*X41/100) -> 0 | Z41: =IF(OR(Setup!C16="",Setup!C16=0,Y41=0),"—",Y41/Setup!C16) -> —
C42: =Setup!B17 -> 0 | E42: =IF(D42="",0,(Setup!C5*Setup!C4)*D42/100) -> 0 | F42: =IF(OR(Setup!C17="",Setup!C17=0,E42=0),"—",E42/Setup!C17) -> — | H42: =Setup!B17 -> 0 | J42: =IF(I42="",0,(Setup!C5*Setup!C4)*I42/100) -> 0 | K42: =IF(OR(Setup!C17="",Setup!C17=0,J42=0),"—",J42/Setup!C17) -> — | M42: =Setup!B17 -> 0 | O42: =IF(N42="",0,(Setup!C5*Setup!C4)*N42/100) -> 0 | P42: =IF(OR(Setup!C17="",Setup!C17=0,O42=0),"—",O42/Setup!C17) -> — | R42: =Setup!B17 -> 0 | T42: =IF(S42="",0,(Setup!C5*Setup!C4)*S42/100) -> 0 | U42: =IF(OR(Setup!C17="",Setup!C17=0,T42=0),"—",T42/Setup!C17) -> — | W42: =Setup!B17 -> 0 | Y42: =IF(X42="",0,(Setup!C5*Setup!C4)*X42/100) -> 0 | Z42: =IF(OR(Setup!C17="",Setup!C17=0,Y42=0),"—",Y42/Setup!C17) -> —
C43: =Setup!B18 -> 0 | E43: =IF(D43="",0,(Setup!C5*Setup!C4)*D43/100) -> 0 | F43: =IF(OR(Setup!C18="",Setup!C18=0,E43=0),"—",E43/Setup!C18) -> — | H43: =Setup!B18 -> 0 | J43: =IF(I43="",0,(Setup!C5*Setup!C4)*I43/100) -> 0 | K43: =IF(OR(Setup!C18="",Setup!C18=0,J43=0),"—",J43/Setup!C18) -> — | M43: =Setup!B18 -> 0 | O43: =IF(N43="",0,(Setup!C5*Setup!C4)*N43/100) -> 0 | P43: =IF(OR(Setup!C18="",Setup!C18=0,O43=0),"—",O43/Setup!C18) -> — | R43: =Setup!B18 -> 0 | T43: =IF(S43="",0,(Setup!C5*Setup!C4)*S43/100) -> 0 | U43: =IF(OR(Setup!C18="",Setup!C18=0,T43=0),"—",T43/Setup!C18) -> — | W43: =Setup!B18 -> 0 | Y43: =IF(X43="",0,(Setup!C5*Setup!C4)*X43/100) -> 0 | Z43: =IF(OR(Setup!C18="",Setup!C18=0,Y43=0),"—",Y43/Setup!C18) -> —
C44: =Setup!B19 -> 0 | E44: =IF(D44="",0,(Setup!C5*Setup!C4)*D44/100) -> 0 | F44: =IF(OR(Setup!C19="",Setup!C19=0,E44=0),"—",E44/Setup!C19) -> — | H44: =Setup!B19 -> 0 | J44: =IF(I44="",0,(Setup!C5*Setup!C4)*I44/100) -> 0 | K44: =IF(OR(Setup!C19="",Setup!C19=0,J44=0),"—",J44/Setup!C19) -> — | M44: =Setup!B19 -> 0 | O44: =IF(N44="",0,(Setup!C5*Setup!C4)*N44/100) -> 0 | P44: =IF(OR(Setup!C19="",Setup!C19=0,O44=0),"—",O44/Setup!C19) -> — | R44: =Setup!B19 -> 0 | T44: =IF(S44="",0,(Setup!C5*Setup!C4)*S44/100) -> 0 | U44: =IF(OR(Setup!C19="",Setup!C19=0,T44=0),"—",T44/Setup!C19) -> — | W44: =Setup!B19 -> 0 | Y44: =IF(X44="",0,(Setup!C5*Setup!C4)*X44/100) -> 0 | Z44: =IF(OR(Setup!C19="",Setup!C19=0,Y44=0),"—",Y44/Setup!C19) -> —
...

Sheet Plate Layout
A1: 96-WELL PLATE LAYOUT
B3: Row | C3: Time | D3: Transfection | E3: Receptor | F3: 1 | G3: 2 | H3: 3 | I3: 4 | J3: 5 | K3: 6 | L3: 7 | M3: 8 | N3: 9 | O3: 10 | P3: 11 | Q3: 12
F4: Buffer | H4: AngII | J4: 46204 | L4: losartan 10µM | N4: Losartan 1 µM
B6: A | D6: pcDNA
B7: B | D7: 0,5% hibit
B8: C | D8: 0,5% hibit +arr
B9: D | D9: 1% hibit
B10: E | D10: 1% hibit +arr
B11: F | D11: 0% hibit
B12: G | D12: 1% hibit +arr
B13: H

Sheet Dilutions
A1: SERIAL DILUTION CALCULATOR
C2: 20ul + 40,4ul h20dd + 0,73 ul dmso + 139ul hbss | J2: 60,4 + 0,73ul DMSO + 139 ul hbss | Q2: losa + h20 buff
B3: AngII | I3: Ang(1-7) | P3: Losartan | W3: Compound 4 | AD3: Compound 5 | AK3: Compound 6
B4: Vol for wells (µl) | D4: 200 | I4: Vol for wells (µl) | K4: 200 | P4: Vol for wells (µl) | R4: 200 | W4: Vol for wells (µl) | Y4: 200 | AD4: Vol for wells (µl) | AF4: 200 | AK4: Vol for wells (µl) | AM4: 200
B5: Dilution factor | D5: 10 | I5: Dilution factor | K5: 10 | P5: Dilution factor | R5: 10 | W5: Dilution factor | Y5: 2 | AD5: Dilution factor | AF5: 2 | AK5: Dilution factor | AM5: 2
B6: Stock conc. (µM) | D6: 100 | I6: Stock conc. (µM) | K6: 1000 | P6: Stock conc. (µM) | R6: 30000 | W6: Stock conc. (µM) | Y6: 100 | AD6: Stock conc. (µM) | AF6: 100 | AK6: Stock conc. (µM) | AM6: 100
B7: Margin (×) | D7: 1 | I7: Margin (×) | K7: 1 | P7: Margin (×) | R7: 1 | W7: Margin (×) | Y7: 1.2 | AD7: Margin (×) | AF7: 1.2 | AK7: Margin (×) | AM7: 1.2
B8: Dilution Bank | I8: Dilution Bank | P8: Dilution Bank | W8: Dilution Bank | AD8: Dilution Bank | AK8: Dilution Bank
B9: Conc. (logM) | C9: Conc. (µM) | D9: Vol to prepare (µl) | E9: From prev. or stock (µl) | F9: Buffer (µl) | G9: Left for wells (µl) | I9: Conc. (logM) | J9: Conc. (µM) | K9: Vol to prepare (µl) | L9: From prev. or stock (µl) | M9: Buffer (µl) | N9: Left for wells (µl) | P9: Conc. (logM) | Q9: Conc. (µM) | R9: Vol to prepare (µl) | S9: From prev. or stock (µl) | T9: Buffer (µl) | U9: Left for wells (µl) | W9: Conc. (logM) | X9: Conc. (µM) | Y9: Vol to prepare (µl) | Z9: From prev. or stock (µl) | AA9: Buffer (µl) | AB9: Left for wells (µl) | AD9: Conc. (logM) | AE9: Conc. (µM) | AF9: Vol to prepare (µl) | AG9: From prev. or stock (µl) | AH9: Buffer (µl) | AI9: Left for wells (µl) | AK9: Conc. (logM) | AL9: Conc. (µM) | AM9: Vol to prepare (µl) | AN9: From prev. or stock (µl) | AO9: Buffer (µl) | AP9: Left for wells (µl)
B10: -6 | C10: =IF(B10="","",(10^B10)*1000000) -> 1 | D10: =IF(B10="","",IF(B11="",CEILING(D4*D7,1),CEILING(D4*D7+(D11*C11)/C10,1))) -> 200 | E10: =IF(B10="","",(D10*C10*D5)/D6) -> 20 | F10: =IF(B10="","",D10-E10) -> 180 | G10: =IF(B10="","",IF(B11="",D10,D10-E11)) -> 200 | I10: -4.52 | J10: =IF(I10="","",(10^I10)*1000000) -> 30.199517 | K10: =IF(I10="","",IF(I11="",CEILING(K4*K7,1),CEILING(K4*K7+(K11*J11)/J10,1))) -> 200 | L10: =IF(I10="","",(K10*J10*K5)/K6) -> 60.399034 | M10: =IF(I10="","",K10-L10) -> 139.60097 | N10: =IF(I10="","",IF(I11="",K10,K10-L11)) -> 200 | P10: -5 | Q10: =IF(P10="","",(10^P10)*1000000) -> 10 | R10: =IF(P10="","",IF(P11="",CEILING(R4*R7,1),CEILING(R4*R7+(R11*Q11)/Q10,1))) -> 220 | S10: =IF(P10="","",(R10*Q10*R5)/R6) -> 0.73333333 | T10: =IF(P10="","",R10-S10) -> 219.26667 | U10: =IF(P10="","",IF(P11="",R10,R10-S11)) -> 200 | X10: =IF(W10="","",(10^W10)*1000000) | Y10: =IF(W10="","",IF(W11="",CEILING(Y4*Y7,1),CEILING(Y4*Y7+(Y11*X11)/X10,1))) | Z10: =IF(W10="","",(Y10*X10*Y5)/Y6) | AA10: =IF(W10="","",Y10-Z10) | AB10: =IF(W10="","",IF(W11="",Y10,Y10-Z11)) | AE10: =IF(AD10="","",(10^AD10)*1000000) | AF10: =IF(AD10="","",IF(AD11="",CEILING(AF4*AF7,1),CEILING(AF4*AF7+(AF11*AE11)/AE10,1))) | AG10: =IF(AD10="","",(AF10*AE10*AF5)/AF6) | AH10: =IF(AD10="","",AF10-AG10) | AI10: =IF(AD10="","",IF(AD11="",AF10,AF10-AG11)) | AL10: =IF(AK10="","",(10^AK10)*1000000) | AM10: =IF(AK10="","",IF(AK11="",CEILING(AM4*AM7,1),CEILING(AM4*AM7+(AM11*AL11)/AL10,1))) | AN10: =IF(AK10="","",(AM10*AL10*AM5)/AM6) | AO10: =IF(AK10="","",AM10-AN10) | AP10: =IF(AK10="","",IF(AK11="",AM10,AM10-AN11))
C11: =IF(B11="","",(10^B11)*1000000) | D11: =IF(B11="","",IF(B12="",CEILING(D4*D7,1),CEILING(D4*D7+(D12*C12)/C11,1))) | E11: =IF(B11="","",(D11*C11)/C10) | F11: =IF(B11="","",D11-E11) | G11: =IF(B11="","",IF(B12="",D11,D11-E12)) | J11: =IF(I11="","",(10^I11)*1000000) | K11: =IF(I11="","",IF(I12="",CEILING(K4*K7,1),CEILING(K4*K7+(K12*J12)/J11,1))) | L11: =IF(I11="","",(K11*J11)/J10) | M11: =IF(I11="","",K11-L11) | N11: =IF(I11="","",IF(I12="",K11,K11-L12)) | P11: -6 | Q11: =IF(P11="","",(10^P11)*1000000) -> 1 | R11: =IF(P11="","",IF(P12="",CEILING(R4*R7,1),CEILING(R4*R7+(R12*Q12)/Q11,1))) -> 200 | S11: =IF(P11="","",(R11*Q11)/Q10) -> 20 | T11: =IF(P11="","",R11-S11) -> 180 | U11: =IF(P11="","",IF(P12="",R11,R11-S12)) -> 200 | X11: =IF(W11="","",(10^W11)*1000000) | Y11: =IF(W11="","",IF(W12="",CEILING(Y4*Y7,1),CEILING(Y4*Y7+(Y12*X12)/X11,1))) | Z11: =IF(W11="","",(Y11*X11)/X10) | AA11: =IF(W11="","",Y11-Z11) | AB11: =IF(W11="","",IF(W12="",Y11,Y11-Z12)) | AE11: =IF(AD11="","",(10^AD11)*1000000) | AF11: =IF(AD11="","",IF(AD12="",CEILING(AF4*AF7,1),CEILING(AF4*AF7+(AF12*AE12)/AE11,1))) | AG11: =IF(AD11="","",(AF11*AE11)/AE10) | AH11: =IF(AD11="","",AF11-AG11) | AI11: =IF(AD11="","",IF(AD12="",AF11,AF11-AG12)) | AL11: =IF(AK11="","",(10^AK11)*1000000) | AM11: =IF(AK11="","",IF(AK12="",CEILING(AM4*AM7,1),CEILING(AM4*AM7+(AM12*AL12)/AL11,1))) | AN11: =IF(AK11="","",(AM11*AL11)/AL10) | AO11: =IF(AK11="","",AM11-AN11) | AP11: =IF(AK11="","",IF(AK12="",AM11,AM11-AN12))
C12: =IF(B12="","",(10^B12)*1000000) | D12: =IF(B12="","",IF(B13="",CEILING(D4*D7,1),CEILING(D4*D7+(D13*C13)/C12,1))) | E12: =IF(B12="","",(D12*C12)/C11) | F12: =IF(B12="","",D12-E12) | G12: =IF(B12="","",IF(B13="",D12,D12-E13)) | J12: =IF(I12="","",(10^I12)*1000000) | K12: =IF(I12="","",IF(I13="",CEILING(K4*K7,1),CEILING(K4*K7+(K13*J13)/J12,1))) | L12: =IF(I12="","",(K12*J12)/J11) | M12: =IF(I12="","",K12-L12) | N12: =IF(I12="","",IF(I13="",K12,K12-L13)) | Q12: =IF(P12="","",(10^P12)*1000000) | R12: =IF(P12="","",IF(P13="",CEILING(R4*R7,1),CEILING(R4*R7+(R13*Q13)/Q12,1))) | S12: =IF(P12="","",(R12*Q12)/Q11) | T12: =IF(P12="","",R12-S12) | U12: =IF(P12="","",IF(P13="",R12,R12-S13)) | X12: =IF(W12="","",(10^W12)*1000000) | Y12: =IF(W12="","",IF(W13="",CEILING(Y4*Y7,1),CEILING(Y4*Y7+(Y13*X13)/X12,1))) | Z12: =IF(W12="","",(Y12*X12)/X11) | AA12: =IF(W12="","",Y12-Z12) | AB12: =IF(W12="","",IF(W13="",Y12,Y12-Z13)) | AE12: =IF(AD12="","",(10^AD12)*1000000) | AF12: =IF(AD12="","",IF(AD13="",CEILING(AF4*AF7,1),CEILING(AF4*AF7+(AF13*AE13)/AE12,1))) | AG12: =IF(AD12="","",(AF12*AE12)/AE11) | AH12: =IF(AD12="","",AF12-AG12) | AI12: =IF(AD12="","",IF(AD13="",AF12,AF12-AG13)) | AL12: =IF(AK12="","",(10^AK12)*1000000) | AM12: =IF(AK12="","",IF(AK13="",CEILING(AM4*AM7,1),CEILING(AM4*AM7+(AM13*AL13)/AL12,1))) | AN12: =IF(AK12="","",(AM12*AL12)/AL11) | AO12: =IF(AK12="","",AM12-AN12) | AP12: =IF(AK12="","",IF(AK13="",AM12,AM12-AN13))
C13: =IF(B13="","",(10^B13)*1000000) | D13: =IF(B13="","",IF(B14="",CEILING(D4*D7,1),CEILING(D4*D7+(D14*C14)/C13,1))) | E13: =IF(B13="","",(D13*C13)/C12) | F13: =IF(B13="","",D13-E13) | G13: =IF(B13="","",IF(B14="",D13,D13-E14)) | J13: =IF(I13="","",(10^I13)*1000000) | K13: =IF(I13="","",IF(I14="",CEILING(K4*K7,1),CEILING(K4*K7+(K14*J14)/J13,1))) | L13: =IF(I13="","",(K13*J13)/J12) | M13: =IF(I13="","",K13-L13) | N13: =IF(I13="","",IF(I14="",K13,K13-L14)) | Q13: =IF(P13="","",(10^P13)*1000000) | R13: =IF(P13="","",IF(P14="",CEILING(R4*R7,1),CEILING(R4*R7+(R14*Q14)/Q13,1))) | S13: =IF(P13="","",(R13*Q13)/Q12) | T13: =IF(P13="","",R13-S13) | U13: =IF(P13="","",IF(P14="",R13,R13-S14)) | X13: =IF(W13="","",(10^W13)*1000000) | Y13: =IF(W13="","",IF(W14="",CEILING(Y4*Y7,1),CEILING(Y4*Y7+(Y14*X14)/X13,1))) | Z13: =IF(W13="","",(Y13*X13)/X12) | AA13: =IF(W13="","",Y13-Z13) | AB13: =IF(W13="","",IF(W14="",Y13,Y13-Z14)) | AE13: =IF(AD13="","",(10^AD13)*1000000) | AF13: =IF(AD13="","",IF(AD14="",CEILING(AF4*AF7,1),CEILING(AF4*AF7+(AF14*AE14)/AE13,1))) | AG13: =IF(AD13="","",(AF13*AE13)/AE12) | AH13: =IF(AD13="","",AF13-AG13) | AI13: =IF(AD13="","",IF(AD14="",AF13,AF13-AG14)) | AL13: =IF(AK13="","",(10^AK13)*1000000) | AM13: =IF(AK13="","",IF(AK14="",CEILING(AM4*AM7,1),CEILING(AM4*AM7+(AM14*AL14)/AL13,1))) | AN13: =IF(AK13="","",(AM13*AL13)/AL12) | AO13: =IF(AK13="","",AM13-AN13) | AP13: =IF(AK13="","",IF(AK14="",AM13,AM13-AN14))
C14: =IF(B14="","",(10^B14)*1000000) | D14: =IF(B14="","",IF(B15="",CEILING(D4*D7,1),CEILING(D4*D7+(D15*C15)/C14,1))) | E14: =IF(B14="","",(D14*C14)/C13) | F14: =IF(B14="","",D14-E14) | G14: =IF(B14="","",IF(B15="",D14,D14-E15)) | J14: =IF(I14="","",(10^I14)*1000000) | K14: =IF(I14="","",IF(I15="",CEILING(K4*K7,1),CEILING(K4*K7+(K15*J15)/J14,1))) | L14: =IF(I14="","",(K14*J14)/J13) | M14: =IF(I14="","",K14-L14) | N14: =IF(I14="","",IF(I15="",K14,K14-L15)) | Q14: =IF(P14="","",(10^P14)*1000000) | R14: =IF(P14="","",IF(P15="",CEILING(R4*R7,1),CEILING(R4*R7+(R15*Q15)/Q14,1))) | S14: =IF(P14="","",(R14*Q14)/Q13) | T14: =IF(P14="","",R14-S14) | U14: =IF(P14="","",IF(P15="",R14,R14-S15)) | X14: =IF(W14="","",(10^W14)*1000000) | Y14: =IF(W14="","",IF(W15="",CEILING(Y4*Y7,1),CEILING(Y4*Y7+(Y15*X15)/X14,1))) | Z14: =IF(W14="","",(Y14*X14)/X13) | AA14: =IF(W14="","",Y14-Z14) | AB14: =IF(W14="","",IF(W15="",Y14,Y14-Z15)) | AE14: =IF(AD14="","",(10^AD14)*1000000) | AF14: =IF(AD14="","",IF(AD15="",CEILING(AF4*AF7,1),CEILING(AF4*AF7+(AF15*AE15)/AE14,1))) | AG14: =IF(AD14="","",(AF14*AE14)/AE13) | AH14: =IF(AD14="","",AF14-AG14) | AI14: =IF(AD14="","",IF(AD15="",AF14,AF14-AG15)) | AL14: =IF(AK14="","",(10^AK14)*1000000) | AM14: =IF(AK14="","",IF(AK15="",CEILING(AM4*AM7,1),CEILING(AM4*AM7+(AM15*AL15)/AL14,1))) | AN14: =IF(AK14="","",(AM14*AL14)/AL13) | AO14: =IF(AK14="","",AM14-AN14) | AP14: =IF(AK14="","",IF(AK15="",AM14,AM14-AN15))
C15: =IF(B15="","",(10^B15)*1000000) | D15: =IF(B15="","",IF(B16="",CEILING(D4*D7,1),CEILING(D4*D7+(D16*C16)/C15,1))) | E15: =IF(B15="","",(D15*C15)/C14) | F15: =IF(B15="","",D15-E15) | G15: =IF(B15="","",IF(B16="",D15,D15-E16)) | J15: =IF(I15="","",(10^I15)*1000000) | K15: =IF(I15="","",IF(I16="",CEILING(K4*K7,1),CEILING(K4*K7+(K16*J16)/J15,1))) | L15: =IF(I15="","",(K15*J15)/J14) | M15: =IF(I15="","",K15-L15) | N15: =IF(I15="","",IF(I16="",K15,K15-L16)) | Q15: =IF(P15="","",(10^P15)*1000000) | R15: =IF(P15="","",IF(P16="",CEILING(R4*R7,1),CEILING(R4*R7+(R16*Q16)/Q15,1))) | S15: =IF(P15="","",(R15*Q15)/Q14) | T15: =IF(P15="","",R15-S15) | U15: =IF(P15="","",IF(P16="",R15,R15-S16)) | X15: =IF(W15="","",(10^W15)*1000000) | Y15: =IF(W15="","",IF(W16="",CEILING(Y4*Y7,1),CEILING(Y4*Y7+(Y16*X16)/X15,1))) | Z15: =IF(W15="","",(Y15*X15)/X14) | AA15: =IF(W15="","",Y15-Z15) | AB15: =IF(W15="","",IF(W16="",Y15,Y15-Z16)) | AE15: =IF(AD15="","",(10^AD15)*1000000) | AF15: =IF(AD15="","",IF(AD16="",CEILING(AF4*AF7,1),CEILING(AF4*AF7+(AF16*AE16)/AE15,1))) | AG15: =IF(AD15="","",(AF15*AE15)/AE14) | AH15: =IF(AD15="","",AF15-AG15) | AI15: =IF(AD15="","",IF(AD16="",AF15,AF15-AG16)) | AL15: =IF(AK15="","",(10^AK15)*1000000) | AM15: =IF(AK15="","",IF(AK16="",CEILING(AM4*AM7,1),CEILING(AM4*AM7+(AM16*AL16)/AL15,1))) | AN15: =IF(AK15="","",(AM15*AL15)/AL14) | AO15: =IF(AK15="","",AM15-AN15) | AP15: =IF(AK15="","",IF(AK16="",AM15,AM15-AN16))
C16: =IF(B16="","",(10^B16)*1000000) | D16: =IF(B16="","",IF(B17="",CEILING(D4*D7,1),CEILING(D4*D7+(D17*C17)/C16,1))) | E16: =IF(B16="","",(D16*C16)/C15) | F16: =IF(B16="","",D16-E16) | G16: =IF(B16="","",IF(B17="",D16,D16-E17)) | J16: =IF(I16="","",(10^I16)*1000000) | K16: =IF(I16="","",IF(I17="",CEILING(K4*K7,1),CEILING(K4*K7+(K17*J17)/J16,1))) | L16: =IF(I16="","",(K16*J16)/J15) | M16: =IF(I16="","",K16-L16) | N16: =IF(I16="","",IF(I17="",K16,K16-L17)) | Q16: =IF(P16="","",(10^P16)*1000000) | R16: =IF(P16="","",IF(P17="",CEILING(R4*R7,1),CEILING(R4*R7+(R17*Q17)/Q16,1))) | S16: =IF(P16="","",(R16*Q16)/Q15) | T16: =IF(P16="","",R16-S16) | U16: =IF(P16="","",IF(P17="",R16,R16-S17)) | X16: =IF(W16="","",(10^W16)*1000000) | Y16: =IF(W16="","",IF(W17="",CEILING(Y4*Y7,1),CEILING(Y4*Y7+(Y17*X17)/X16,1))) | Z16: =IF(W16="","",(Y16*X16)/X15) | AA16: =IF(W16="","",Y16-Z16) | AB16: =IF(W16="","",IF(W17="",Y16,Y16-Z17)) | AE16: =IF(AD16="","",(10^AD16)*1000000) | AF16: =IF(AD16="","",IF(AD17="",CEILING(AF4*AF7,1),CEILING(AF4*AF7+(AF17*AE17)/AE16,1))) | AG16: =IF(AD16="","",(AF16*AE16)/AE15) | AH16: =IF(AD16="","",AF16-AG16) | AI16: =IF(AD16="","",IF(AD17="",AF16,AF16-AG17)) | AL16: =IF(AK16="","",(10^AK16)*1000000) | AM16: =IF(AK16="","",IF(AK17="",CEILING(AM4*AM7,1),CEILING(AM4*AM7+(AM17*AL17)/AL16,1))) | AN16: =IF(AK16="","",(AM16*AL16)/AL15) | AO16: =IF(AK16="","",AM16-AN16) | AP16: =IF(AK16="","",IF(AK17="",AM16,AM16-AN17))
C17: =IF(B17="","",(10^B17)*1000000) | D17: =IF(B17="","",IF(B18="",CEILING(D4*D7,1),CEILING(D4*D7+(D18*C18)/C17,1))) | E17: =IF(B17="","",(D17*C17)/C16) | F17: =IF(B17="","",D17-E17) | G17: =IF(B17="","",IF(B18="",D17,D17-E18)) | J17: =IF(I17="","",(10^I17)*1000000) | K17: =IF(I17="","",IF(I18="",CEILING(K4*K7,1),CEILING(K4*K7+(K18*J18)/J17,1))) | L17: =IF(I17="","",(K17*J17)/J16) | M17: =IF(I17="","",K17-L17) | N17: =IF(I17="","",IF(I18="",K17,K17-L18)) | Q17: =IF(P17="","",(10^P17)*1000000) | R17: =IF(P17="","",IF(P18="",CEILING(R4*R7,1),CEILING(R4*R7+(R18*Q18)/Q17,1))) | S17: =IF(P17="","",(R17*Q17)/Q16) | T17: =IF(P17="","",R17-S17) | U17: =IF(P17="","",IF(P18="",R17,R17-S18)) | X17: =IF(W17="","",(10^W17)*1000000) | Y17: =IF(W17="","",IF(W18="",CEILING(Y4*Y7,1),CEILING(Y4*Y7+(Y18*X18)/X17,1))) | Z17: =IF(W17="","",(Y17*X17)/X16) | AA17: =IF(W17="","",Y17-Z17) | AB17: =IF(W17="","",IF(W18="",Y17,Y17-Z18)) | AE17: =IF(AD17="","",(10^AD17)*1000000) | AF17: =IF(AD17="","",IF(AD18="",CEILING(AF4*AF7,1),CEILING(AF4*AF7+(AF18*AE18)/AE17,1))) | AG17: =IF(AD17="","",(AF17*AE17)/AE16) | AH17: =IF(AD17="","",AF17-AG17) | AI17: =IF(AD17="","",IF(AD18="",AF17,AF17-AG18)) | AL17: =IF(AK17="","",(10^AK17)*1000000) | AM17: =IF(AK17="","",IF(AK18="",CEILING(AM4*AM7,1),CEILING(AM4*AM7+(AM18*AL18)/AL17,1))) | AN17: =IF(AK17="","",(AM17*AL17)/AL16) | AO17: =IF(AK17="","",AM17-AN17) | AP17: =IF(AK17="","",IF(AK18="",AM17,AM17-AN18))
C18: =IF(B18="","",(10^B18)*1000000) | D18: =IF(B18="","",IF(B19="",CEILING(D4*D7,1),CEILING(D4*D7+(D19*C19)/C18,1))) | E18: =IF(B18="","",(D18*C18)/C17) | F18: =IF(B18="","",D18-E18) | G18: =IF(B18="","",IF(B19="",D18,D18-E19)) | J18: =IF(I18="","",(10^I18)*1000000) | K18: =IF(I18="","",IF(I19="",CEILING(K4*K7,1),CEILING(K4*K7+(K19*J19)/J18,1))) | L18: =IF(I18="","",(K18*J18)/J17) | M18: =IF(I18="","",K18-L18) | N18: =IF(I18="","",IF(I19="",K18,K18-L19)) | Q18: =IF(P18="","",(10^P18)*1000000) | R18: =IF(P18="","",IF(P19="",CEILING(R4*R7,1),CEILING(R4*R7+(R19*Q19)/Q18,1))) | S18: =IF(P18="","",(R18*Q18)/Q17) | T18: =IF(P18="","",R18-S18) | U18: =IF(P18="","",IF(P19="",R18,R18-S19)) | X18: =IF(W18="","",(10^W18)*1000000) | Y18: =IF(W18="","",IF(W19="",CEILING(Y4*Y7,1),CEILING(Y4*Y7+(Y19*X19)/X18,1))) | Z18: =IF(W18="","",(Y18*X18)/X17) | AA18: =IF(W18="","",Y18-Z18) | AB18: =IF(W18="","",IF(W19="",Y18,Y18-Z19)) | AE18: =IF(AD18="","",(10^AD18)*1000000) | AF18: =IF(AD18="","",IF(AD19="",CEILING(AF4*AF7,1),CEILING(AF4*AF7+(AF19*AE19)/AE18,1))) | AG18: =IF(AD18="","",(AF18*AE18)/AE17) | AH18: =IF(AD18="","",AF18-AG18) | AI18: =IF(AD18="","",IF(AD19="",AF18,AF18-AG19)) | AL18: =IF(AK18="","",(10^AK18)*1000000) | AM18: =IF(AK18="","",IF(AK19="",CEILING(AM4*AM7,1),CEILING(AM4*AM7+(AM19*AL19)/AL18,1))) | AN18: =IF(AK18="","",(AM18*AL18)/AL17) | AO18: =IF(AK18="","",AM18-AN18) | AP18: =IF(AK18="","",IF(AK19="",AM18,AM18-AN19))
C19: =IF(B19="","",(10^B19)*1000000) | D19: =IF(B19="","",IF(B20="",CEILING(D4*D7,1),CEILING(D4*D7+(D20*C20)/C19,1))) | E19: =IF(B19="","",(D19*C19)/C18) | F19: =IF(B19="","",D19-E19) | G19: =IF(B19="","",IF(B20="",D19,D19-E20)) | J19: =IF(I19="","",(10^I19)*1000000) | K19: =IF(I19="","",IF(I20="",CEILING(K4*K7,1),CEILING(K4*K7+(K20*J20)/J19,1))) | L19: =IF(I19="","",(K19*J19)/J18) | M19: =IF(I19="","",K19-L19) | N19: =IF(I19="","",IF(I20="",K19,K19-L20)) | Q19: =IF(P19="","",(10^P19)*1000000) | R19: =IF(P19="","",IF(P20="",CEILING(R4*R7,1),CEILING(R4*R7+(R20*Q20)/Q19,1))) | S19: =IF(P19="","",(R19*Q19)/Q18) | T19: =IF(P19="","",R19-S19) | U19: =IF(P19="","",IF(P20="",R19,R19-S20)) | X19: =IF(W19="","",(10^W19)*1000000) | Y19: =IF(W19="","",IF(W20="",CEILING(Y4*Y7,1),CEILING(Y4*Y7+(Y20*X20)/X19,1))) | Z19: =IF(W19="","",(Y19*X19)/X18) | AA19: =IF(W19="","",Y19-Z19) | AB19: =IF(W19="","",IF(W20="",Y19,Y19-Z20)) | AE19: =IF(AD19="","",(10^AD19)*1000000) | AF19: =IF(AD19="","",IF(AD20="",CEILING(AF4*AF7,1),CEILING(AF4*AF7+(AF20*AE20)/AE19,1))) | AG19: =IF(AD19="","",(AF19*AE19)/AE18) | AH19: =IF(AD19="","",AF19-AG19) | AI19: =IF(AD19="","",IF(AD20="",AF19,AF19-AG20)) | AL19: =IF(AK19="","",(10^AK19)*1000000) | AM19: =IF(AK19="","",IF(AK20="",CEILING(AM4*AM7,1),CEILING(AM4*AM7+(AM20*AL20)/AL19,1))) | AN19: =IF(AK19="","",(AM19*AL19)/AL18) | AO19: =IF(AK19="","",AM19-AN19) | AP19: =IF(AK19="","",IF(AK20="",AM19,AM19-AN20))
C20: =IF(B20="","",(10^B20)*1000000) | D20: =IF(B20="","",IF(B21="",CEILING(D4*D7,1),CEILING(D4*D7+(D21*C21)/C20,1))) | E20: =IF(B20="","",(D20*C20)/C19) | F20: =IF(B20="","",D20-E20) | G20: =IF(B20="","",IF(B21="",D20,D20-E21)) | J20: =IF(I20="","",(10^I20)*1000000) | K20: =IF(I20="","",IF(I21="",CEILING(K4*K7,1),CEILING(K4*K7+(K21*J21)/J20,1))) | L20: =IF(I20="","",(K20*J20)/J19) | M20: =IF(I20="","",K20-L20) | N20: =IF(I20="","",IF(I21="",K20,K20-L21)) | Q20: =IF(P20="","",(10^P20)*1000000) | R20: =IF(P20="","",IF(P21="",CEILING(R4*R7,1),CEILING(R4*R7+(R21*Q21)/Q20,1))) | S20: =IF(P20="","",(R20*Q20)/Q19) | T20: =IF(P20="","",R20-S20) | U20: =IF(P20="","",IF(P21="",R20,R20-S21)) | X20: =IF(W20="","",(10^W20)*1000000) | Y20: =IF(W20="","",IF(W21="",CEILING(Y4*Y7,1),CEILING(Y4*Y7+(Y21*X21)/X20,1))) | Z20: =IF(W20="","",(Y20*X20)/X19) | AA20: =IF(W20="","",Y20-Z20) | AB20: =IF(W20="","",IF(W21="",Y20,Y20-Z21)) | AE20: =IF(AD20="","",(10^AD20)*1000000) | AF20: =IF(AD20="","",IF(AD21="",CEILING(AF4*AF7,1),CEILING(AF4*AF7+(AF21*AE21)/AE20,1))) | AG20: =IF(AD20="","",(AF20*AE20)/AE19) | AH20: =IF(AD20="","",AF20-AG20) | AI20: =IF(AD20="","",IF(AD21="",AF20,AF20-AG21)) | AL20: =IF(AK20="","",(10^AK20)*1000000) | AM20: =IF(AK20="","",IF(AK21="",CEILING(AM4*AM7,1),CEILING(AM4*AM7+(AM21*AL21)/AL20,1))) | AN20: =IF(AK20="","",(AM20*AL20)/AL19) | AO20: =IF(AK20="","",AM20-AN20) | AP20: =IF(AK20="","",IF(AK21="",AM20,AM20-AN21))
C21: =IF(B21="","",(10^B21)*1000000) | D21: =IF(B21="","",CEILING(D4*D7,1)) | E21: =IF(B21="","",(D21*C21)/C20) | F21: =IF(B21="","",D21-E21) | G21: =IF(B21="","",D21) | J21: =IF(I21="","",(10^I21)*1000000) | K21: =IF(I21="","",CEILING(K4*K7,1)) | L21: =IF(I21="","",(K21*J21)/J20) | M21: =IF(I21="","",K21-L21) | N21: =IF(I21="","",K21) | Q21: =IF(P21="","",(10^P21)*1000000) | R21: =IF(P21="","",CEILING(R4*R7,1)) | S21: =IF(P21="","",(R21*Q21)/Q20) | T21: =IF(P21="","",R21-S21) | U21: =IF(P21="","",R21) | X21: =IF(W21="","",(10^W21)*1000000) | Y21: =IF(W21="","",CEILING(Y4*Y7,1)) | Z21: =IF(W21="","",(Y21*X21)/X20) | AA21: =IF(W21="","",Y21-Z21) | AB21: =IF(W21="","",Y21) | AE21: =IF(AD21="","",(10^AD21)*1000000) | AF21: =IF(AD21="","",CEILING(AF4*AF7,1)) | AG21: =IF(AD21="","",(AF21*AE21)/AE20) | AH21: =IF(AD21="","",AF21-AG21) | AI21: =IF(AD21="","",AF21) | AL21: =IF(AK21="","",(10^AK21)*1000000) | AM21: =IF(AK21="","",CEILING(AM4*AM7,1)) | AN21: =IF(AK21="","",(AM21*AL21)/AL20) | AO21: =IF(AK21="","",AM21-AN21) | AP21: =IF(AK21="","",AM21)
B22: Total buffer needed (µl): | F22: =IF(COUNTA(B10:B21)=0,"",SUMPRODUCT(IF(ISNUMBER(F10:F21),F10:F21,0))) -> 0 | I22: Total buffer needed (µl): | M22: =IF(COUNTA(I10:I21)=0,"",SUMPRODUCT(IF(ISNUMBER(M10:M21),M10:M21,0))) -> 0 | P22: Total buffer needed (µl): | T22: =IF(COUNTA(P10:P21)=0,"",SUMPRODUCT(IF(ISNUMBER(T10:T21),T10:T21,0))) -> 0 | W22: Total buffer needed (µl): | AA22: =IF(COUNTA(W10:W21)=0,"",SUMPRODUCT(IF(ISNUMBER(AA10:AA21),AA10:AA21,0))) | AD22: Total buffer needed (µl): | AH22: =IF(COUNTA(AD10:AD21)=0,"",SUMPRODUCT(IF(ISNUMBER(AH10:AH21),AH10:AH21,0))) | AK22: Total buffer needed (µl): | AO22: =IF(COUNTA(AK10:AK21)=0,"",SUMPRODUCT(IF(ISNUMBER(AO10:AO21),AO10:AO21,0)))
B23: Stock needed (µl): | F23: =IF(E10="","",E10) -> 20 | I23: Stock needed (µl): | M23: =IF(L10="","",L10) -> 60.399034 | P23: Stock needed (µl): | T23: =IF(S10="","",S10) -> 0.73333333 | W23: Stock needed (µl): | AA23: =IF(Z10="","",Z10) | AD23: Stock needed (µl): | AH23: =IF(AG10="","",AG10) | AK23: Stock needed (µl): | AO23: =IF(AN10="","",AN10)
B26: BUFFER SUMMARY
B27: buffer for all compounds (µl): | C27: 30% h20 buff = 1,2ml h20 dd + 2,8ml hbss
